2024-12-14 12:52:30: WARNING [MainThread] get_async_session(28): Session rollback because of exception: (sqlalchemy.dialects.postgresql.asyncpg.ProgrammingError) <class 'asyncpg.exceptions.UndefinedTableError'>: relation "user" does not exist
[SQL: SELECT "user".username AS user_username, "user".role AS user_role, "user".first_name AS user_first_name, "user".last_name AS user_last_name, "user".age AS user_age, "user".experience AS user_experience, "user".created_at AS user_created_at, "user".updated_at AS user_updated_at, "user".id AS user_id 
FROM "user" 
WHERE "user".id = $1::UUID]
[parameters: (UUID('00000000-0000-4000-8000-00002853cf0f'),)]
(Background on this error at: https://sqlalche.me/e/20/f405)
2024-12-14 12:53:52: WARNING [MainThread] get_async_session(28): Session rollback because of exception: (sqlalchemy.dialects.postgresql.asyncpg.ProgrammingError) <class 'asyncpg.exceptions.UndefinedTableError'>: relation "user" does not exist
[SQL: SELECT "user".username AS user_username, "user".role AS user_role, "user".first_name AS user_first_name, "user".last_name AS user_last_name, "user".age AS user_age, "user".experience AS user_experience, "user".created_at AS user_created_at, "user".updated_at AS user_updated_at, "user".id AS user_id 
FROM "user" 
WHERE "user".id = $1::UUID]
[parameters: (UUID('00000000-0000-4000-8000-00002853cf0f'),)]
(Background on this error at: https://sqlalche.me/e/20/f405)
2024-12-14 12:58:58: WARNING [MainThread] get_async_session(28): Session rollback because of exception: 'NoneType' object has no attribute 'answer'
2024-12-14 12:59:04: WARNING [MainThread] get_async_session(28): Session rollback because of exception: 'NoneType' object has no attribute 'answer'
2024-12-14 12:59:06: WARNING [MainThread] get_async_session(28): Session rollback because of exception: 'NoneType' object has no attribute 'answer'
2024-12-14 12:59:07: WARNING [MainThread] get_async_session(28): Session rollback because of exception: 'NoneType' object has no attribute 'answer'
2024-12-14 16:11:38: WARNING [MainThread] get_async_session(28): Session rollback because of exception: 'NoneType' object has no attribute 'answer'
2024-12-14 16:11:43: WARNING [MainThread] get_async_session(28): Session rollback because of exception: 'NoneType' object has no attribute 'answer'
2024-12-14 16:11:45: WARNING [MainThread] get_async_session(28): Session rollback because of exception: 'NoneType' object has no attribute 'answer'
2024-12-14 18:11:07: WARNING [MainThread] get_async_session(28): Session rollback because of exception: 'NoneType' object has no attribute 'answer'
2024-12-14 18:27:32: WARNING [MainThread] get_async_session(28): Session rollback because of exception: 'NoneType' object has no attribute 'answer'
2024-12-14 18:54:59: WARNING [MainThread] get_async_session(28): Session rollback because of exception: name 'show_grid' is not defined
2024-12-14 22:44:40: WARNING [MainThread] get_async_session(28): Session rollback because of exception: Textual SQL expression 'SELECT * FROM event WHERE...' should be explicitly declared as text('SELECT * FROM event WHERE...')
2024-12-14 22:54:12: WARNING [MainThread] get_async_session(28): Session rollback because of exception: 'NoneType' object has no attribute 'reply_text'
2024-12-14 22:54:15: WARNING [MainThread] get_async_session(28): Session rollback because of exception: 'NoneType' object has no attribute 'reply_text'
2024-12-15 08:34:25: WARNING [MainThread] get_async_session(28): Session rollback because of exception: 'NoneType' object has no attribute 'reply_text'
2024-12-15 09:28:43: WARNING [MainThread] get_async_session(28): Session rollback because of exception: 'title' is an invalid keyword argument for Event
2024-12-15 09:28:50: WARNING [MainThread] get_async_session(28): Session rollback because of exception: 'NoneType' object has no attribute 'reply_text'
2024-12-15 09:52:57: WARNING [MainThread] get_async_session(28): Session rollback because of exception: 'NoneType' object has no attribute 'reply_text'
2024-12-15 10:02:38: WARNING [MainThread] get_async_session(28): Session rollback because of exception: 'NoneType' object has no attribute 'reply_text'
2024-12-15 10:05:25: WARNING [MainThread] get_async_session(28): Session rollback because of exception: 'NoneType' object has no attribute 'reply_text'
2024-12-15 10:05:27: WARNING [MainThread] get_async_session(28): Session rollback because of exception: 'NoneType' object has no attribute 'reply_text'
2024-12-15 10:05:27: WARNING [MainThread] get_async_session(28): Session rollback because of exception: 'NoneType' object has no attribute 'reply_text'
2024-12-15 10:08:53: WARNING [MainThread] get_async_session(28): Session rollback because of exception: 'NoneType' object has no attribute 'reply_text'
2024-12-15 10:08:56: WARNING [MainThread] get_async_session(28): Session rollback because of exception: 'NoneType' object has no attribute 'reply_text'
2024-12-15 10:18:45: WARNING [MainThread] get_async_session(28): Session rollback because of exception: 'NoneType' object has no attribute 'reply_text'
2024-12-15 16:08:35: WARNING [MainThread] get_async_session(28): Session rollback because of exception: 'NoneType' object has no attribute 'reply_text'
2024-12-15 16:08:36: WARNING [MainThread] get_async_session(28): Session rollback because of exception: 'NoneType' object has no attribute 'reply_text'
2024-12-15 16:09:49: WARNING [MainThread] get_async_session(28): Session rollback because of exception: 'NoneType' object has no attribute 'reply_text'
2024-12-15 16:22:20: WARNING [MainThread] get_async_session(28): Session rollback because of exception: (sqlalchemy.dialects.postgresql.asyncpg.Error) <class 'asyncpg.exceptions.DataError'>: invalid input for query argument $1: 'input' (invalid UUID 'input': length must be between 32..36 characters, got 5)
[SQL: SELECT event.title AS event_title, event.category_id AS event_category_id, event.location AS event_location, event.people_amount AS event_people_amount, event.experience AS event_experience, event.date_time AS event_date_time, event.organizer_id AS event_organizer_id, event.description AS event_description, event.created_at AS event_created_at, event.updated_at AS event_updated_at, event.id AS event_id 
FROM event 
WHERE event.id = $1::UUID]
[parameters: ('input',)]
(Background on this error at: https://sqlalche.me/e/20/dbapi)
2024-12-15 22:49:21: WARNING [MainThread] get_async_session(28): Session rollback because of exception: [WinError 1225] The remote computer refused the network connection
2024-12-15 22:49:40: WARNING [MainThread] get_async_session(28): Session rollback because of exception: [WinError 1225] The remote computer refused the network connection
2024-12-15 23:27:45: WARNING [MainThread] get_async_session(28): Session rollback because of exception: (sqlalchemy.dialects.postgresql.asyncpg.ProgrammingError) <class 'asyncpg.exceptions.UndefinedTableError'>: relation "user" does not exist
[SQL: SELECT "user".username AS user_username, "user".role AS user_role, "user".first_name AS user_first_name, "user".last_name AS user_last_name, "user".age AS user_age, "user".experience AS user_experience, "user".created_at AS user_created_at, "user".updated_at AS user_updated_at, "user".id AS user_id 
FROM "user" 
WHERE "user".id = $1::UUID]
[parameters: (UUID('00000000-0000-4000-8000-00002853cf0f'),)]
(Background on this error at: https://sqlalche.me/e/20/f405)
2024-12-15 23:27:45: WARNING [MainThread] get_async_session(28): Session rollback because of exception: (sqlalchemy.dialects.postgresql.asyncpg.ProgrammingError) <class 'asyncpg.exceptions.UndefinedTableError'>: relation "user" does not exist
[SQL: SELECT "user".username AS user_username, "user".role AS user_role, "user".first_name AS user_first_name, "user".last_name AS user_last_name, "user".age AS user_age, "user".experience AS user_experience, "user".created_at AS user_created_at, "user".updated_at AS user_updated_at, "user".id AS user_id 
FROM "user" 
WHERE "user".id = $1::UUID]
[parameters: (UUID('00000000-0000-4000-8000-00002853cf0f'),)]
(Background on this error at: https://sqlalche.me/e/20/f405)
2024-12-15 23:32:21: WARNING [MainThread] get_async_session(28): Session rollback because of exception: Textual SQL expression 'SELECT id, title FROM eve...' should be explicitly declared as text('SELECT id, title FROM eve...')
2024-12-15 23:32:33: WARNING [MainThread] get_async_session(28): Session rollback because of exception: Textual SQL expression 'SELECT id, title FROM eve...' should be explicitly declared as text('SELECT id, title FROM eve...')
